<sdf version='1.7'>
  <world name='default'>
    <light name='sun' type='directional'>
      <cast_shadows>1</cast_shadows>
      <pose>0 0 10 0 -0 0</pose>
      <diffuse>0.8 0.8 0.8 1</diffuse>
      <specular>0.2 0.2 0.2 1</specular>
      <attenuation>
        <range>1000</range>
        <constant>0.9</constant>
        <linear>0.01</linear>
        <quadratic>0.001</quadratic>
      </attenuation>
      <direction>-0.5 0.1 -0.9</direction>
      <spot>
        <inner_angle>0</inner_angle>
        <outer_angle>0</outer_angle>
        <falloff>0</falloff>
      </spot>
    </light>
    <model name='ground_plane'>
      <static>1</static>
      <link name='link'>
        <collision name='collision'>
          <geometry>
            <plane>
              <normal>0 0 1</normal>
              <size>100 100</size>
            </plane>
          </geometry>
          <surface>
            <friction>
              <ode>
                <mu>100</mu>
                <mu2>50</mu2>
              </ode>
              <torsional>
                <ode/>
              </torsional>
            </friction>
            <contact>
              <ode/>
            </contact>
            <bounce/>
          </surface>
          <max_contacts>10</max_contacts>
        </collision>
        <visual name='visual'>
          <cast_shadows>0</cast_shadows>
          <geometry>
            <plane>
              <normal>0 0 1</normal>
              <size>100 100</size>
            </plane>
          </geometry>
          <material>
            <script>
              <uri>file://media/materials/scripts/gazebo.material</uri>
              <name>Gazebo/Grey</name>
            </script>
          </material>
        </visual>
        <self_collide>0</self_collide>
        <enable_wind>0</enable_wind>
        <kinematic>0</kinematic>
      </link>
    </model>
    <gravity>0 0 -9.8</gravity>
    <magnetic_field>6e-06 2.3e-05 -4.2e-05</magnetic_field>
    <atmosphere type='adiabatic'/>
    <physics type='ode'>
      <max_step_size>0.001</max_step_size>
      <real_time_factor>1</real_time_factor>
      <real_time_update_rate>1000</real_time_update_rate>
    </physics>
    <scene>
      <ambient>0.4 0.4 0.4 1</ambient>
      <background>0.7 0.7 0.7 1</background>
      <shadows>1</shadows>
    </scene>
    <wind/>
    <spherical_coordinates>
      <surface_model>EARTH_WGS84</surface_model>
      <latitude_deg>0</latitude_deg>
      <longitude_deg>0</longitude_deg>
      <elevation>0</elevation>
      <heading_deg>0</heading_deg>
    </spherical_coordinates>
    <model name='unit_cylinder'>
      <pose>0.98 -0.046831 0.5 0 -0 0</pose>
      <link name='link'>
        <inertial>
          <mass>1</mass>
          <inertia>
            <ixx>0.145833</ixx>
            <ixy>0</ixy>
            <ixz>0</ixz>
            <iyy>0.145833</iyy>
            <iyz>0</iyz>
            <izz>0.125</izz>
          </inertia>
          <pose>0 0 0 0 -0 0</pose>
        </inertial>
        <collision name='collision'>
          <geometry>
            <cylinder>
              <radius>0.500001</radius>
              <length>1</length>
            </cylinder>
          </geometry>
          <max_contacts>10</max_contacts>
          <surface>
            <contact>
              <ode/>
            </contact>
            <bounce/>
            <friction>
              <torsional>
                <ode/>
              </torsional>
              <ode/>
            </friction>
          </surface>
        </collision>
        <visual name='visual'>
          <geometry>
            <cylinder>
              <radius>0.500001</radius>
              <length>1</length>
            </cylinder>
          </geometry>
          <material>
            <script>
              <name>Gazebo/Grey</name>
              <uri>file://media/materials/scripts/gazebo.material</uri>
            </script>
          </material>
        </visual>
        <self_collide>0</self_collide>
        <enable_wind>0</enable_wind>
        <kinematic>0</kinematic>
      </link>
    </model>
    <state world_name='default'>
      <sim_time>198 112000000</sim_time>
      <real_time>190 413051509</real_time>
      <wall_time>1739828338 811687573</wall_time>
      <iterations>25363</iterations>
      <model name='ground_plane'>
        <pose>0 0 0 0 -0 0</pose>
        <scale>1 1 1</scale>
        <link name='link'>
          <pose>0 0 0 0 -0 0</pose>
          <velocity>0 0 0 0 -0 0</velocity>
          <acceleration>0 0 0 0 -0 0</acceleration>
          <wrench>0 0 0 0 -0 0</wrench>
        </link>
      </model>
      <model name='jackal'>
        <pose>0.008873 -0.000182 0.063498 0 2e-06 -0.002056</pose>
        <scale>1 1 1</scale>
        <link name='base_link'>
          <pose>0.008873 -0.000182 0.063498 0 2e-06 -0.002056</pose>
          <velocity>6.8e-05 1e-06 2.1e-05 1e-06 -9e-06 0</velocity>
          <acceleration>0 0 -0 0 -0 0</acceleration>
          <wrench>5e-06 0 -0 0 -0 0</wrench>
        </link>
        <link name='front_left_wheel_link'>
          <pose>0.140258 0.187343 0.097997 -7e-06 0.087652 -0.002057</pose>
          <velocity>6.8e-05 1e-06 2.1e-05 -1.2e-05 0.000673 0</velocity>
          <acceleration>0 0 0 0 3e-06 0</acceleration>
          <wrench>0 0 0 0 -0 0</wrench>
        </link>
        <link name='front_right_wheel_link'>
          <pose>0.139486 -0.188246 0.097997 -6e-06 0.087996 -0.002057</pose>
          <velocity>6.8e-05 1e-06 2e-05 -1.1e-05 0.000673 0</velocity>
          <acceleration>0 0 0 0 3e-06 0</acceleration>
          <wrench>0 0 0 0 -0 0</wrench>
        </link>
        <link name='kinova_arm_arm_link'>
          <pose>0.14716 -0.024213 0.490748 1.57081 0.793572 0.655452</pose>
          <velocity>2.1e-05 -3.6e-05 2.2e-05 0.000104 -0.00013 -0.001977</velocity>
          <acceleration>-1e-06 -0 0 -2e-06 1e-06 -3e-06</acceleration>
          <wrench>-1e-06 -0 0 0 -0 0</wrench>
        </link>
        <link name='kinova_arm_end_effector_link'>
          <pose>0.535812 0.300763 0.508923 3.11367 1.20562 -2.51319</pose>
          <velocity>0.000345 -0.001002 -0.000536 -0.000823 0.001782 -0.001988</velocity>
          <acceleration>-3e-06 -1e-06 1e-06 -2e-06 -2e-06 0</acceleration>
          <wrench>-0 -0 0 0 -0 0</wrench>
        </link>
        <link name='kinova_arm_forearm_link'>
          <pose>0.3054 0.097445 0.687112 1.57078 1.20574 -2.48616</pose>
          <velocity>0.000236 -0.000369 5.3e-05 -0.001182 0.001532 -0.001974</velocity>
          <acceleration>0 -0 0 1e-05 4e-06 -6e-06</acceleration>
          <wrench>0 -0 0 0 -0 0</wrench>
        </link>
        <link name='kinova_arm_left_finger_dist_link'>
          <pose>0.612601 0.38208 0.466823 -3.02338 -0.346291 -2.84967</pose>
          <velocity>0.001185 -0.002948 -0.000577 -0.010755 -0.005495 -0.034049</velocity>
          <acceleration>-9.6e-05 -3.7e-05 3.4e-05 -5.8e-05 -3.1e-05 0.000159</acceleration>
          <wrench>-1e-06 -0 0 0 -0 0</wrench>
        </link>
        <link name='kinova_arm_left_finger_prox_link'>
          <pose>0.568973 0.364963 0.484238 3.07235 -0.358801 -2.3181</pose>
          <velocity>0.000428 -0.001088 -0.000648 -0.011924 -0.006351 -0.037847</velocity>
          <acceleration>2.5e-05 1.5e-05 -1e-05 0 -0.000163 1.3e-05</acceleration>
          <wrench>0 0 -0 0 -0 0</wrench>
        </link>
        <link name='kinova_arm_lower_wrist_link'>
          <pose>0.396886 0.19301 0.637132 3.12015 1.20566 -2.50911</pose>
          <velocity>0.00035 -0.000607 -0.000198 -0.000875 0.001747 -0.002117</velocity>
          <acceleration>-2e-06 -1e-06 0 5e-06 4e-06 -1e-06</acceleration>
          <wrench>-1e-06 -1e-06 0 0 -0 0</wrench>
        </link>
        <link name='kinova_arm_right_finger_dist_link'>
          <pose>0.626848 0.35916 0.467642 -3.11312 -0.364107 -2.59298</pose>
          <velocity>0.000619 -0.001346 -0.000789 -0.000821 0.001764 -0.002001</velocity>
          <acceleration>-3e-06 -3e-06 -0 -2.1e-05 -3.8e-05 -0.000125</acceleration>
          <wrench>-0 -0 -0 0 -0 0</wrench>
        </link>
        <link name='kinova_arm_right_finger_prox_link'>
          <pose>0.606105 0.31657 0.48363 3.12607 -0.364854 -2.46969</pose>
          <velocity>0.000331 -0.001163 -0.000675 -0.002372 0.000639 -0.007008</velocity>
          <acceleration>-3e-06 0 0 -1.6e-05 -4.8e-05 -4.8e-05</acceleration>
          <wrench>-0 0 0 0 -0 0</wrench>
        </link>
        <link name='kinova_arm_shoulder_link'>
          <pose>0.128873 -0.00043 0.375747 3e-06 1.2e-05 0.655433</pose>
          <velocity>6.5e-05 -1e-06 2.2e-05 -1.9e-05 2.9e-05 -0.002003</velocity>
          <acceleration>0 -0 0 1e-06 1e-06 -1e-06</acceleration>
          <wrench>0 -0 0 0 -0 0</wrench>
        </link>
        <link name='kinova_arm_upper_wrist_link'>
          <pose>0.466434 0.246775 0.573027 3.13238 -0.36503 -2.4833</pose>
          <velocity>0.000351 -0.000811 -0.000368 -0.000843 0.00177 -0.001979</velocity>
          <acceleration>-2e-06 -1e-06 0 7e-06 5e-06 -6e-06</acceleration>
          <wrench>-1e-06 -0 0 0 -0 0</wrench>
        </link>
        <link name='rear_left_wheel_link'>
          <pose>-0.121741 0.187881 0.097998 -8e-06 0.08243 -0.002057</pose>
          <velocity>6.8e-05 1e-06 1.9e-05 -9e-06 0.000675 0</velocity>
          <acceleration>0 -0 -0 0 3e-06 0</acceleration>
          <wrench>0 -0 -0 0 -0 0</wrench>
        </link>
        <link name='rear_right_wheel_link'>
          <pose>-0.122513 -0.187708 0.097998 -7e-06 0.082412 -0.002057</pose>
          <velocity>6.8e-05 1e-06 1.8e-05 -9e-06 0.000675 0</velocity>
          <acceleration>0 -0 -0 0 3e-06 0</acceleration>
          <wrench>0 -0 -0 0 -0 0</wrench>
        </link>
      </model>
      <model name='unit_cylinder'>
        <pose>0.98 -0.04683 0.46599 0 -1e-06 0</pose>
        <scale>0.531655 0.531655 0.931984</scale>
        <link name='link'>
          <pose>0.98 -0.04683 0.46599 0 -1e-06 0</pose>
          <velocity>0 0 0 0 -0 0</velocity>
          <acceleration>0 0 -9.8 0 -0 0</acceleration>
          <wrench>0 0 -9.8 0 -0 0</wrench>
        </link>
      </model>
      <model name='unit_sphere'>
        <pose>0.531653 -0.038728 0.9 0 -0 0</pose>
        <scale>0.32 0.32 0.32</scale>
        <link name='link'>
          <pose>0.531653 -0.038728 0.9 0 -0 0</pose>
          <velocity>0 0 0 0 -0 0</velocity>
          <acceleration>0 0 0 0 -0 0</acceleration>
          <wrench>0 0 0 0 -0 0</wrench>
        </link>
      </model>
      <light name='sun'>
        <pose>0 0 10 0 -0 0</pose>
      </light>
    </state>
    <gui fullscreen='0'>
      <camera name='user_camera'>
        <pose>1.05106 7.6532 5.46206 0 0.573796 -1.63901</pose>
        <view_controller>ortho</view_controller>
        <projection_type>orthographic</projection_type>
      </camera>
    </gui>
    <model name='jackal'>
      <link name='base_link'>
        <inertial>
          <pose>0.012847 0.001795 0.095589 0 -0 0</pose>
          <mass>18.5101</mass>
          <inertia>
            <ixx>0.454651</ixx>
            <ixy>-0.000791168</ixy>
            <ixz>0.0303676</ixz>
            <iyy>0.5618</iyy>
            <iyz>1.55173e-05</iyz>
            <izz>0.478986</izz>
          </inertia>
        </inertial>
        <collision name='base_link_fixed_joint_lump__chassis_link_collision'>
          <pose>0 0 0.092 0 -0 0</pose>
          <geometry>
            <box>
              <size>0.42 0.31 0.184</size>
            </box>
          </geometry>
          <surface>
            <contact>
              <ode/>
            </contact>
            <friction>
              <ode/>
              <torsional>
                <ode/>
              </torsional>
            </friction>
            <bounce/>
          </surface>
          <max_contacts>10</max_contacts>
        </collision>
        <collision name='base_link_fixed_joint_lump__kinova_arm_base_link_collision_1'>
          <pose>0.12 0 0.184 0 -0 0</pose>
          <geometry>
            <mesh>
              <scale>1 1 1</scale>
              <uri>/home/georgiossidiropoulos/catkin_ws/src/ros_kortex/kortex_description/arms/gen3_lite/6dof/meshes/base_link.STL</uri>
            </mesh>
          </geometry>
          <surface>
            <contact>
              <ode/>
            </contact>
            <friction>
              <ode/>
              <torsional>
                <ode/>
              </torsional>
            </friction>
            <bounce/>
          </surface>
          <max_contacts>10</max_contacts>
        </collision>
        <collision name='base_link_fixed_joint_lump__velodyne_base_link_collision_2'>
          <pose>-0.12 0 0.41985 0 -0 0</pose>
          <geometry>
            <cylinder>
              <length>0.0717</length>
              <radius>0.0516</radius>
            </cylinder>
          </geometry>
          <max_contacts>10</max_contacts>
          <surface>
            <contact>
              <ode/>
            </contact>
            <bounce/>
            <friction>
              <torsional>
                <ode/>
              </torsional>
              <ode/>
            </friction>
          </surface>
        </collision>
        <collision name='base_link_fixed_joint_lump__velodyne_collision_3'>
          <pose>-0.12 0 0.4217 0 -0 0</pose>
          <geometry>
            <sphere>
              <radius>0</radius>
            </sphere>
          </geometry>
          <surface>
            <contact>
              <ode/>
            </contact>
            <friction>
              <ode/>
              <torsional>
                <ode/>
              </torsional>
            </friction>
            <bounce/>
          </surface>
          <max_contacts>10</max_contacts>
        </collision>
        <visual name='base_link_fixed_joint_lump__chassis_link_visual'>
          <pose>0 0 -0.0655 1.5708 -0 1.5708</pose>
          <geometry>
            <mesh>
              <scale>1 1 1</scale>
              <uri>/opt/ros/noetic/share/jackal_description/meshes/jackal-base.stl</uri>
            </mesh>
          </geometry>
          <material>
            <script>
              <name>Gazebo/DarkGrey</name>
              <uri>file://media/materials/scripts/gazebo.material</uri>
            </script>
          </material>
        </visual>
        <visual name='base_link_fixed_joint_lump__front_fender_link_visual_1'>
          <pose>0 0 0 0 -0 0</pose>
          <geometry>
            <mesh>
              <scale>1 1 1</scale>
              <uri>/opt/ros/noetic/share/jackal_description/meshes/jackal-fender.stl</uri>
            </mesh>
          </geometry>
          <material>
            <script>
              <name>Gazebo/Yellow</name>
              <uri>file://media/materials/scripts/gazebo.material</uri>
            </script>
          </material>
        </visual>
        <visual name='base_link_fixed_joint_lump__kinova_arm_base_link_visual_2'>
          <pose>0.12 0 0.184 0 -0 0</pose>
          <geometry>
            <mesh>
              <scale>1 1 1</scale>
              <uri>/home/georgiossidiropoulos/catkin_ws/src/ros_kortex/kortex_description/arms/gen3_lite/6dof/meshes/base_link.STL</uri>
            </mesh>
          </geometry>
          <material>
            <script>
              <name>Kortex/Gray</name>
              <uri>file://media/materials/scripts/gazebo.material</uri>
            </script>
          </material>
        </visual>
        <visual name='base_link_fixed_joint_lump__rear_vlp16_leg1_visual_3'>
          <pose>-0.07 0.05 0.284 0 -0 0</pose>
          <geometry>
            <cylinder>
              <length>0.2</length>
              <radius>0.003</radius>
            </cylinder>
          </geometry>
        </visual>
        <visual name='base_link_fixed_joint_lump__rear_vlp16_leg2_visual_4'>
          <pose>-0.07 -0.05 0.284 0 -0 0</pose>
          <geometry>
            <cylinder>
              <length>0.2</length>
              <radius>0.003</radius>
            </cylinder>
          </geometry>
        </visual>
        <visual name='base_link_fixed_joint_lump__rear_vlp16_leg3_visual_5'>
          <pose>-0.17 0.05 0.284 0 -0 0</pose>
          <geometry>
            <cylinder>
              <length>0.2</length>
              <radius>0.003</radius>
            </cylinder>
          </geometry>
        </visual>
        <visual name='base_link_fixed_joint_lump__rear_vlp16_leg4_visual_6'>
          <pose>-0.17 -0.05 0.284 0 -0 0</pose>
          <geometry>
            <cylinder>
              <length>0.2</length>
              <radius>0.003</radius>
            </cylinder>
          </geometry>
        </visual>
        <visual name='base_link_fixed_joint_lump__rear_vlp16_plate_visual_7'>
          <pose>-0.12 0 0.383 0 -0 0</pose>
          <geometry>
            <box>
              <size>0.1 0.1 0.002</size>
            </box>
          </geometry>
        </visual>
        <visual name='base_link_fixed_joint_lump__velodyne_base_link_visual_8'>
          <pose>-0.12 0 0.384 0 -0 0</pose>
          <geometry>
            <mesh>
              <scale>1 1 1</scale>
              <uri>/home/georgiossidiropoulos/catkin_ws/src/velodyne_simulator/velodyne_description/meshes/VLP16_base_1.dae</uri>
            </mesh>
          </geometry>
        </visual>
        <visual name='base_link_fixed_joint_lump__velodyne_base_link_visual_9'>
          <pose>-0.12 0 0.384 0 -0 0</pose>
          <geometry>
            <mesh>
              <scale>1 1 1</scale>
              <uri>/home/georgiossidiropoulos/catkin_ws/src/velodyne_simulator/velodyne_description/meshes/VLP16_base_2.dae</uri>
            </mesh>
          </geometry>
        </visual>
        <visual name='base_link_fixed_joint_lump__velodyne_visual_10'>
          <pose>-0.12 0 0.384 0 -0 0</pose>
          <geometry>
            <mesh>
              <scale>1 1 1</scale>
              <uri>/home/georgiossidiropoulos/catkin_ws/src/velodyne_simulator/velodyne_description/meshes/VLP16_scan.dae</uri>
            </mesh>
          </geometry>
        </visual>
        <visual name='base_link_fixed_joint_lump__navsat_link_visual_11'>
          <pose>-0.18 0.126 0.1895 0 -0 0</pose>
          <geometry>
            <cylinder>
              <length>0.016</length>
              <radius>0.026</radius>
            </cylinder>
          </geometry>
          <material>
            <script>
              <name>Gazebo/DarkGrey</name>
              <uri>file://media/materials/scripts/gazebo.material</uri>
            </script>
          </material>
        </visual>
        <visual name='base_link_fixed_joint_lump__rear_fender_link_visual_12'>
          <pose>0 0 0 0 -0 3.14159</pose>
          <geometry>
            <mesh>
              <scale>1 1 1</scale>
              <uri>/opt/ros/noetic/share/jackal_description/meshes/jackal-fender.stl</uri>
            </mesh>
          </geometry>
          <material>
            <script>
              <name>Gazebo/Yellow</name>
              <uri>file://media/materials/scripts/gazebo.material</uri>
            </script>
          </material>
        </visual>
        <sensor name='velodyne-VLP16' type='ray'>
          <visualize>0</visualize>
          <update_rate>10</update_rate>
          <ray>
            <scan>
              <horizontal>
                <samples>314</samples>
                <resolution>1</resolution>
                <min_angle>-1.75</min_angle>
                <max_angle>1.75</max_angle>
              </horizontal>
              <vertical>
                <samples>16</samples>
                <resolution>1</resolution>
                <min_angle>-0.261799</min_angle>
                <max_angle>0.785398</max_angle>
              </vertical>
            </scan>
            <range>
              <min>0.4</min>
              <max>3</max>
              <resolution>0.001</resolution>
            </range>
            <noise>
              <type>gaussian</type>
              <mean>0</mean>
              <stddev>0</stddev>
            </noise>
          </ray>
          <plugin name='gazebo_ros_laser_controller' filename='libgazebo_ros_velodyne_laser.so'>
            <topicName>/velodyne_points</topicName>
            <frameName>velodyne</frameName>
            <min_range>0.3</min_range>
            <max_range>3.0</max_range>
            <gaussianNoise>0.008</gaussianNoise>
            <robotNamespace>/</robotNamespace>
          </plugin>
          <pose>-0.12 0 0.4217 0 -0 0</pose>
        </sensor>
        <gravity>1</gravity>
        <self_collide>0</self_collide>
        <enable_wind>0</enable_wind>
        <kinematic>0</kinematic>
      </link>
      <joint name='front_left_wheel' type='revolute'>
        <pose relative_to='base_link'>0.131 0.187795 0.0345 0 -0 0</pose>
        <parent>base_link</parent>
        <child>front_left_wheel_link</child>
        <axis>
          <xyz>0 1 0</xyz>
          <limit>
            <lower>-1e+16</lower>
            <upper>1e+16</upper>
          </limit>
          <dynamics>
            <spring_reference>0</spring_reference>
            <spring_stiffness>0</spring_stiffness>
          </dynamics>
        </axis>
      </joint>
      <link name='front_left_wheel_link'>
        <pose relative_to='front_left_wheel'>0 0 0 0 -0 0</pose>
        <inertial>
          <pose>0 0 0 0 -0 0</pose>
          <mass>0.477</mass>
          <inertia>
            <ixx>0.0013</ixx>
            <ixy>0</ixy>
            <ixz>0</ixz>
            <iyy>0.0024</iyy>
            <iyz>0</iyz>
            <izz>0.0013</izz>
          </inertia>
        </inertial>
        <collision name='front_left_wheel_link_collision'>
          <pose>0 0 0 1.5708 -0 0</pose>
          <geometry>
            <cylinder>
              <length>0.04</length>
              <radius>0.098</radius>
            </cylinder>
          </geometry>
          <surface>
            <contact>
              <ode>
                <kp>1e+07</kp>
                <kd>1</kd>
              </ode>
            </contact>
            <friction>
              <ode>
                <mu>0.5</mu>
                <mu2>0.5</mu2>
                <fdir1>1 0 0</fdir1>
              </ode>
              <torsional>
                <ode/>
              </torsional>
            </friction>
            <bounce/>
          </surface>
          <max_contacts>10</max_contacts>
        </collision>
        <visual name='front_left_wheel_link_visual'>
          <pose>0 0 0 1.5708 -0 0</pose>
          <geometry>
            <mesh>
              <scale>1 1 1</scale>
              <uri>/opt/ros/noetic/share/jackal_description/meshes/jackal-wheel.stl</uri>
            </mesh>
          </geometry>
          <material>
            <script>
              <name>Gazebo/DarkGrey</name>
              <uri>file://media/materials/scripts/gazebo.material</uri>
            </script>
          </material>
        </visual>
        <self_collide>0</self_collide>
        <enable_wind>0</enable_wind>
        <kinematic>0</kinematic>
      </link>
      <joint name='front_right_wheel' type='revolute'>
        <pose relative_to='base_link'>0.131 -0.187795 0.0345 0 -0 0</pose>
        <parent>base_link</parent>
        <child>front_right_wheel_link</child>
        <axis>
          <xyz>0 1 0</xyz>
          <limit>
            <lower>-1e+16</lower>
            <upper>1e+16</upper>
          </limit>
          <dynamics>
            <spring_reference>0</spring_reference>
            <spring_stiffness>0</spring_stiffness>
          </dynamics>
        </axis>
      </joint>
      <link name='front_right_wheel_link'>
        <pose relative_to='front_right_wheel'>0 0 0 0 -0 0</pose>
        <inertial>
          <pose>0 0 0 0 -0 0</pose>
          <mass>0.477</mass>
          <inertia>
            <ixx>0.0013</ixx>
            <ixy>0</ixy>
            <ixz>0</ixz>
            <iyy>0.0024</iyy>
            <iyz>0</iyz>
            <izz>0.0013</izz>
          </inertia>
        </inertial>
        <collision name='front_right_wheel_link_collision'>
          <pose>0 0 0 1.5708 -0 0</pose>
          <geometry>
            <cylinder>
              <length>0.04</length>
              <radius>0.098</radius>
            </cylinder>
          </geometry>
          <surface>
            <contact>
              <ode>
                <kp>1e+07</kp>
                <kd>1</kd>
              </ode>
            </contact>
            <friction>
              <ode>
                <mu>0.5</mu>
                <mu2>0.5</mu2>
                <fdir1>1 0 0</fdir1>
              </ode>
              <torsional>
                <ode/>
              </torsional>
            </friction>
            <bounce/>
          </surface>
          <max_contacts>10</max_contacts>
        </collision>
        <visual name='front_right_wheel_link_visual'>
          <pose>0 0 0 1.5708 -0 0</pose>
          <geometry>
            <mesh>
              <scale>1 1 1</scale>
              <uri>/opt/ros/noetic/share/jackal_description/meshes/jackal-wheel.stl</uri>
            </mesh>
          </geometry>
          <material>
            <script>
              <name>Gazebo/DarkGrey</name>
              <uri>file://media/materials/scripts/gazebo.material</uri>
            </script>
          </material>
        </visual>
        <self_collide>0</self_collide>
        <enable_wind>0</enable_wind>
        <kinematic>0</kinematic>
      </link>
      <joint name='kinova_arm_joint_1' type='revolute'>
        <pose relative_to='base_link'>0.12 0 0.31225 0 -0 0</pose>
        <parent>base_link</parent>
        <child>kinova_arm_shoulder_link</child>
        <axis>
          <xyz>0 0 1</xyz>
          <limit>
            <lower>-2.68</lower>
            <upper>2.68</upper>
            <effort>10</effort>
            <velocity>1.6</velocity>
          </limit>
          <dynamics>
            <spring_reference>0</spring_reference>
            <spring_stiffness>0</spring_stiffness>
          </dynamics>
        </axis>
      </joint>
      <link name='kinova_arm_shoulder_link'>
        <pose relative_to='kinova_arm_joint_1'>0 0 0 0 -0 0</pose>
        <inertial>
          <pose>2.5e-05 0.022135 0.099377 0 -0 0</pose>
          <mass>0.959744</mass>
          <inertia>
            <ixx>0.00165947</ixx>
            <ixy>2e-08</ixy>
            <ixz>3.6e-07</ixz>
            <iyy>0.00140355</iyy>
            <iyz>0.00034927</iyz>
            <izz>0.00089493</izz>
          </inertia>
        </inertial>
        <collision name='kinova_arm_shoulder_link_collision'>
          <pose>0 0 0 0 -0 0</pose>
          <geometry>
            <mesh>
              <scale>1 1 1</scale>
              <uri>/home/georgiossidiropoulos/catkin_ws/src/ros_kortex/kortex_description/arms/gen3_lite/6dof/meshes/shoulder_link.STL</uri>
            </mesh>
          </geometry>
          <surface>
            <contact>
              <ode/>
            </contact>
            <friction>
              <ode/>
              <torsional>
                <ode/>
              </torsional>
            </friction>
            <bounce/>
          </surface>
          <max_contacts>10</max_contacts>
        </collision>
        <visual name='kinova_arm_shoulder_link_visual'>
          <pose>0 0 0 0 -0 0</pose>
          <geometry>
            <mesh>
              <scale>1 1 1</scale>
              <uri>/home/georgiossidiropoulos/catkin_ws/src/ros_kortex/kortex_description/arms/gen3_lite/6dof/meshes/shoulder_link.STL</uri>
            </mesh>
          </geometry>
          <material>
            <script>
              <name>Kortex/Gray</name>
              <uri>file://media/materials/scripts/gazebo.material</uri>
            </script>
          </material>
        </visual>
        <self_collide>0</self_collide>
        <enable_wind>0</enable_wind>
        <kinematic>0</kinematic>
      </link>
      <joint name='kinova_arm_joint_2' type='revolute'>
        <pose relative_to='kinova_arm_shoulder_link'>0 -0.03 0.115 1.5708 -0 0</pose>
        <parent>kinova_arm_shoulder_link</parent>
        <child>kinova_arm_arm_link</child>
        <axis>
          <xyz>0 0 1</xyz>
          <limit>
            <lower>-2.61</lower>
            <upper>2.61</upper>
            <effort>14</effort>
            <velocity>1.6</velocity>
          </limit>
          <dynamics>
            <spring_reference>0</spring_reference>
            <spring_stiffness>0</spring_stiffness>
          </dynamics>
        </axis>
      </joint>
      <link name='kinova_arm_arm_link'>
        <pose relative_to='kinova_arm_joint_2'>0 0 0 0 -0 0</pose>
        <inertial>
          <pose>0.029983 0.211548 0.045303 0 -0 0</pose>
          <mass>1.17756</mass>
          <inertia>
            <ixx>0.0114928</ixx>
            <ixy>1e-06</ixy>
            <ixz>1.6e-07</ixz>
            <iyy>0.00102851</iyy>
            <iyz>0.00140765</iyz>
            <izz>0.0113349</izz>
          </inertia>
        </inertial>
        <collision name='kinova_arm_arm_link_collision'>
          <pose>0 0 0 0 -0 0</pose>
          <geometry>
            <mesh>
              <scale>1 1 1</scale>
              <uri>/home/georgiossidiropoulos/catkin_ws/src/ros_kortex/kortex_description/arms/gen3_lite/6dof/meshes/arm_link.STL</uri>
            </mesh>
          </geometry>
          <surface>
            <contact>
              <ode/>
            </contact>
            <friction>
              <ode/>
              <torsional>
                <ode/>
              </torsional>
            </friction>
            <bounce/>
          </surface>
          <max_contacts>10</max_contacts>
        </collision>
        <visual name='kinova_arm_arm_link_visual'>
          <pose>0 0 0 0 -0 0</pose>
          <geometry>
            <mesh>
              <scale>1 1 1</scale>
              <uri>/home/georgiossidiropoulos/catkin_ws/src/ros_kortex/kortex_description/arms/gen3_lite/6dof/meshes/arm_link.STL</uri>
            </mesh>
          </geometry>
          <material>
            <script>
              <name>Kortex/Gray</name>
              <uri>file://media/materials/scripts/gazebo.material</uri>
            </script>
          </material>
        </visual>
        <self_collide>0</self_collide>
        <enable_wind>0</enable_wind>
        <kinematic>0</kinematic>
      </link>
      <joint name='kinova_arm_joint_3' type='revolute'>
        <pose relative_to='kinova_arm_arm_link'>0 0.28 0 3.14159 -0 0</pose>
        <parent>kinova_arm_arm_link</parent>
        <child>kinova_arm_forearm_link</child>
        <axis>
          <xyz>0 0 1</xyz>
          <limit>
            <lower>-2.61</lower>
            <upper>2.61</upper>
            <effort>10</effort>
            <velocity>1.6</velocity>
          </limit>
          <dynamics>
            <spring_reference>0</spring_reference>
            <spring_stiffness>0</spring_stiffness>
          </dynamics>
        </axis>
      </joint>
      <link name='kinova_arm_forearm_link'>
        <pose relative_to='kinova_arm_joint_3'>0 0 0 0 -0 0</pose>
        <inertial>
          <pose>0.030156 0.095022 0.007356 0 -0 0</pose>
          <mass>0.597677</mass>
          <inertia>
            <ixx>0.00163256</ixx>
            <ixy>7.11e-06</ixy>
            <ixz>1.54e-06</ixz>
            <iyy>0.00029798</iyy>
            <iyz>9.587e-05</iyz>
            <izz>0.00169091</izz>
          </inertia>
        </inertial>
        <collision name='kinova_arm_forearm_link_collision'>
          <pose>0 0 0 0 -0 0</pose>
          <geometry>
            <mesh>
              <scale>1 1 1</scale>
              <uri>/home/georgiossidiropoulos/catkin_ws/src/ros_kortex/kortex_description/arms/gen3_lite/6dof/meshes/forearm_link.STL</uri>
            </mesh>
          </geometry>
          <surface>
            <contact>
              <ode/>
            </contact>
            <friction>
              <ode/>
              <torsional>
                <ode/>
              </torsional>
            </friction>
            <bounce/>
          </surface>
          <max_contacts>10</max_contacts>
        </collision>
        <visual name='kinova_arm_forearm_link_visual'>
          <pose>0 0 0 0 -0 0</pose>
          <geometry>
            <mesh>
              <scale>1 1 1</scale>
              <uri>/home/georgiossidiropoulos/catkin_ws/src/ros_kortex/kortex_description/arms/gen3_lite/6dof/meshes/forearm_link.STL</uri>
            </mesh>
          </geometry>
          <material>
            <script>
              <name>Kortex/Gray</name>
              <uri>file://media/materials/scripts/gazebo.material</uri>
            </script>
          </material>
        </visual>
        <self_collide>0</self_collide>
        <enable_wind>0</enable_wind>
        <kinematic>0</kinematic>
      </link>
      <joint name='kinova_arm_joint_4' type='revolute'>
        <pose relative_to='kinova_arm_forearm_link'>0 -0.14 0.02 1.5708 -0 0</pose>
        <parent>kinova_arm_forearm_link</parent>
        <child>kinova_arm_lower_wrist_link</child>
        <axis>
          <xyz>0 0 1</xyz>
          <limit>
            <lower>-2.6</lower>
            <upper>2.6</upper>
            <effort>7</effort>
            <velocity>1.6</velocity>
          </limit>
          <dynamics>
            <spring_reference>0</spring_reference>
            <spring_stiffness>0</spring_stiffness>
          </dynamics>
        </axis>
      </joint>
      <link name='kinova_arm_lower_wrist_link'>
        <pose relative_to='kinova_arm_joint_4'>0 0 0 0 -0 0</pose>
        <inertial>
          <pose>0.005751 0.010004 0.087192 0 -0 0</pose>
          <mass>0.526934</mass>
          <inertia>
            <ixx>0.00069098</ixx>
            <ixy>2.4e-07</ixy>
            <ixz>0.00016483</ixz>
            <iyy>0.00078519</iyy>
            <iyz>7.4e-07</iyz>
            <izz>0.00034115</izz>
          </inertia>
        </inertial>
        <collision name='kinova_arm_lower_wrist_link_collision'>
          <pose>0 0 0 0 -0 0</pose>
          <geometry>
            <mesh>
              <scale>1 1 1</scale>
              <uri>/home/georgiossidiropoulos/catkin_ws/src/ros_kortex/kortex_description/arms/gen3_lite/6dof/meshes/lower_wrist_link.STL</uri>
            </mesh>
          </geometry>
          <surface>
            <contact>
              <ode/>
            </contact>
            <friction>
              <ode/>
              <torsional>
                <ode/>
              </torsional>
            </friction>
            <bounce/>
          </surface>
          <max_contacts>10</max_contacts>
        </collision>
        <visual name='kinova_arm_lower_wrist_link_visual'>
          <pose>0 0 0 0 -0 0</pose>
          <geometry>
            <mesh>
              <scale>1 1 1</scale>
              <uri>/home/georgiossidiropoulos/catkin_ws/src/ros_kortex/kortex_description/arms/gen3_lite/6dof/meshes/lower_wrist_link.STL</uri>
            </mesh>
          </geometry>
          <material>
            <script>
              <name>Kortex/Gray</name>
              <uri>file://media/materials/scripts/gazebo.material</uri>
            </script>
          </material>
        </visual>
        <self_collide>0</self_collide>
        <enable_wind>0</enable_wind>
        <kinematic>0</kinematic>
      </link>
      <joint name='kinova_arm_joint_5' type='revolute'>
        <pose relative_to='kinova_arm_lower_wrist_link'>0.0285 0 0.105 3.14159 1.57079 3.14159</pose>
        <parent>kinova_arm_lower_wrist_link</parent>
        <child>kinova_arm_upper_wrist_link</child>
        <axis>
          <xyz>0 0 1</xyz>
          <limit>
            <lower>-2.53</lower>
            <upper>2.53</upper>
            <effort>7</effort>
            <velocity>1.6</velocity>
          </limit>
          <dynamics>
            <spring_reference>0</spring_reference>
            <spring_stiffness>0</spring_stiffness>
          </dynamics>
        </axis>
      </joint>
      <link name='kinova_arm_upper_wrist_link'>
        <pose relative_to='kinova_arm_joint_5'>0 0 0 0 -0 0</pose>
        <inertial>
          <pose>0.080565 0.009804 0.018728 0 -0 0</pose>
          <mass>0.580973</mass>
          <inertia>
            <ixx>0.00021268</ixx>
            <ixy>5.21e-06</ixy>
            <ixz>2.91e-06</ixz>
            <iyy>0.00106371</iyy>
            <iyz>1.1e-07</iyz>
            <izz>0.00108465</izz>
          </inertia>
        </inertial>
        <collision name='kinova_arm_upper_wrist_link_collision'>
          <pose>0 0 0 0 -0 0</pose>
          <geometry>
            <mesh>
              <scale>1 1 1</scale>
              <uri>/home/georgiossidiropoulos/catkin_ws/src/ros_kortex/kortex_description/arms/gen3_lite/6dof/meshes/upper_wrist_link.STL</uri>
            </mesh>
          </geometry>
          <surface>
            <contact>
              <ode/>
            </contact>
            <friction>
              <ode/>
              <torsional>
                <ode/>
              </torsional>
            </friction>
            <bounce/>
          </surface>
          <max_contacts>10</max_contacts>
        </collision>
        <visual name='kinova_arm_upper_wrist_link_visual'>
          <pose>0 0 0 0 -0 0</pose>
          <geometry>
            <mesh>
              <scale>1 1 1</scale>
              <uri>/home/georgiossidiropoulos/catkin_ws/src/ros_kortex/kortex_description/arms/gen3_lite/6dof/meshes/upper_wrist_link.STL</uri>
            </mesh>
          </geometry>
          <material>
            <script>
              <name>Kortex/Gray</name>
              <uri>file://media/materials/scripts/gazebo.material</uri>
            </script>
          </material>
        </visual>
        <self_collide>0</self_collide>
        <enable_wind>0</enable_wind>
        <kinematic>0</kinematic>
      </link>
      <joint name='kinova_arm_joint_6' type='revolute'>
        <pose relative_to='kinova_arm_upper_wrist_link'>-0.105 0 0.0285 3.14159 -1.57079 3.14159</pose>
        <parent>kinova_arm_upper_wrist_link</parent>
        <child>kinova_arm_end_effector_link</child>
        <axis>
          <xyz>0 0 1</xyz>
          <limit>
            <lower>-2.6</lower>
            <upper>2.6</upper>
            <effort>7</effort>
            <velocity>3.2</velocity>
          </limit>
          <dynamics>
            <spring_reference>0</spring_reference>
            <spring_stiffness>0</spring_stiffness>
          </dynamics>
        </axis>
      </joint>
      <link name='kinova_arm_end_effector_link'>
        <pose relative_to='kinova_arm_joint_6'>0 0 0 0 -0 0</pose>
        <inertial>
          <pose>4e-06 1.1e-05 0.041397 0 -0 0</pose>
          <mass>0.1395</mass>
          <inertia>
            <ixx>0.00011614</ixx>
            <ixy>1e-08</ixy>
            <ixz>4e-08</ixz>
            <iyy>0.00010327</iyy>
            <iyz>0</iyz>
            <izz>9.707e-05</izz>
          </inertia>
        </inertial>
        <collision name='kinova_arm_end_effector_link_fixed_joint_lump__kinova_arm_gripper_base_link_collision'>
          <pose>0 0 0 0 -0 0</pose>
          <geometry>
            <mesh>
              <scale>1 1 1</scale>
              <uri>/home/georgiossidiropoulos/catkin_ws/src/ros_kortex/kortex_description/grippers/gen3_lite_2f/meshes/gripper_base_link.STL</uri>
            </mesh>
          </geometry>
          <surface>
            <contact>
              <ode/>
            </contact>
            <friction>
              <ode/>
              <torsional>
                <ode/>
              </torsional>
            </friction>
            <bounce/>
          </surface>
          <max_contacts>10</max_contacts>
        </collision>
        <visual name='kinova_arm_end_effector_link_fixed_joint_lump__kinova_arm_gripper_base_link_visual'>
          <pose>0 0 0 0 -0 0</pose>
          <geometry>
            <mesh>
              <scale>1 1 1</scale>
              <uri>/home/georgiossidiropoulos/catkin_ws/src/ros_kortex/kortex_description/grippers/gen3_lite_2f/meshes/gripper_base_link.STL</uri>
            </mesh>
          </geometry>
          <material>
            <script>
              <name>Kortex/Gray</name>
              <uri>file://media/materials/scripts/gazebo.material</uri>
            </script>
          </material>
        </visual>
        <self_collide>0</self_collide>
        <enable_wind>0</enable_wind>
        <kinematic>0</kinematic>
      </link>
      <joint name='kinova_arm_left_finger_bottom_joint' type='revolute'>
        <pose relative_to='kinova_arm_end_effector_link'>0 0.0305 0.070003 3.14159 1.57079 3.14159</pose>
        <parent>kinova_arm_end_effector_link</parent>
        <child>kinova_arm_left_finger_prox_link</child>
        <axis>
          <xyz>0 0 1</xyz>
          <limit>
            <lower>-0.96</lower>
            <upper>0.09</upper>
            <effort>1000</effort>
            <velocity>1000</velocity>
          </limit>
          <dynamics>
            <spring_reference>0</spring_reference>
            <spring_stiffness>0</spring_stiffness>
          </dynamics>
        </axis>
      </joint>
      <link name='kinova_arm_left_finger_prox_link'>
        <pose relative_to='kinova_arm_left_finger_bottom_joint'>0 0 0 0 -0 0</pose>
        <inertial>
          <pose>0.020257 0.006348 7e-05 0 -0 0</pose>
          <mass>0.018385</mass>
          <inertia>
            <ixx>2.29e-06</ixx>
            <ixy>1.43e-06</ixy>
            <ixz>0</ixz>
            <iyy>4.56e-06</iyy>
            <iyz>0</iyz>
            <izz>4.77e-06</izz>
          </inertia>
        </inertial>
        <collision name='kinova_arm_left_finger_prox_link_collision'>
          <pose>0 0 0 0 -0 0</pose>
          <geometry>
            <mesh>
              <scale>1 1 1</scale>
              <uri>/home/georgiossidiropoulos/catkin_ws/src/ros_kortex/kortex_description/grippers/gen3_lite_2f/meshes/left_finger_prox_link.STL</uri>
            </mesh>
          </geometry>
          <surface>
            <contact>
              <ode/>
            </contact>
            <friction>
              <ode/>
              <torsional>
                <ode/>
              </torsional>
            </friction>
            <bounce/>
          </surface>
          <max_contacts>10</max_contacts>
        </collision>
        <visual name='kinova_arm_left_finger_prox_link_visual'>
          <pose>0 0 0 0 -0 0</pose>
          <geometry>
            <mesh>
              <scale>1 1 1</scale>
              <uri>/home/georgiossidiropoulos/catkin_ws/src/ros_kortex/kortex_description/grippers/gen3_lite_2f/meshes/left_finger_prox_link.STL</uri>
            </mesh>
          </geometry>
          <material>
            <script>
              <name>Kortex/Gray</name>
              <uri>file://media/materials/scripts/gazebo.material</uri>
            </script>
          </material>
        </visual>
        <self_collide>0</self_collide>
        <enable_wind>0</enable_wind>
        <kinematic>0</kinematic>
      </link>
      <joint name='kinova_arm_left_finger_tip_joint' type='revolute'>
        <pose relative_to='kinova_arm_left_finger_prox_link'>-0.045636 -0.020423 7e-05 0 -0 0</pose>
        <parent>kinova_arm_left_finger_prox_link</parent>
        <child>kinova_arm_left_finger_dist_link</child>
        <axis>
          <xyz>0 0 -1</xyz>
          <limit>
            <lower>-0.5</lower>
            <upper>0.21</upper>
            <effort>1000</effort>
            <velocity>1000</velocity>
          </limit>
          <dynamics>
            <spring_reference>0</spring_reference>
            <spring_stiffness>0</spring_stiffness>
          </dynamics>
        </axis>
      </joint>
      <link name='kinova_arm_left_finger_dist_link'>
        <pose relative_to='kinova_arm_left_finger_tip_joint'>0 0 0 0 -0 0</pose>
        <inertial>
          <pose>-0.018488 0.001109 0 0 -0 0</pose>
          <mass>0.010748</mass>
          <inertia>
            <ixx>6.3e-07</ixx>
            <ixy>3.2e-07</ixy>
            <ixz>0</ixz>
            <iyy>1.83e-06</iyy>
            <iyz>0</iyz>
            <izz>1.61e-06</izz>
          </inertia>
        </inertial>
        <collision name='kinova_arm_left_finger_dist_link_collision'>
          <pose>0 0 0 0 -0 0</pose>
          <geometry>
            <mesh>
              <scale>1 1 1</scale>
              <uri>/home/georgiossidiropoulos/catkin_ws/src/ros_kortex/kortex_description/grippers/gen3_lite_2f/meshes/left_finger_dist_link.STL</uri>
            </mesh>
          </geometry>
          <surface>
            <contact>
              <ode/>
            </contact>
            <friction>
              <ode/>
              <torsional>
                <ode/>
              </torsional>
            </friction>
            <bounce/>
          </surface>
          <max_contacts>10</max_contacts>
        </collision>
        <visual name='kinova_arm_left_finger_dist_link_visual'>
          <pose>0 0 0 0 -0 0</pose>
          <geometry>
            <mesh>
              <scale>1 1 1</scale>
              <uri>/home/georgiossidiropoulos/catkin_ws/src/ros_kortex/kortex_description/grippers/gen3_lite_2f/meshes/left_finger_dist_link.STL</uri>
            </mesh>
          </geometry>
          <material>
            <script>
              <name>Kortex/Blue</name>
              <uri>file://media/materials/scripts/gazebo.material</uri>
            </script>
          </material>
        </visual>
        <self_collide>0</self_collide>
        <enable_wind>0</enable_wind>
        <kinematic>0</kinematic>
      </link>
      <joint name='kinova_arm_right_finger_bottom_joint' type='revolute'>
        <pose relative_to='kinova_arm_end_effector_link'>0 -0.030501 0.070003 3.14159 1.57079 3.14159</pose>
        <parent>kinova_arm_end_effector_link</parent>
        <child>kinova_arm_right_finger_prox_link</child>
        <axis>
          <xyz>0 0 1</xyz>
          <limit>
            <lower>-0.09</lower>
            <upper>0.96</upper>
            <effort>1000</effort>
            <velocity>0.6</velocity>
          </limit>
          <dynamics>
            <spring_reference>0</spring_reference>
            <spring_stiffness>0</spring_stiffness>
          </dynamics>
        </axis>
      </joint>
      <link name='kinova_arm_right_finger_prox_link'>
        <pose relative_to='kinova_arm_right_finger_bottom_joint'>0 0 0 0 -0 0</pose>
        <inertial>
          <pose>0.020257 0.006348 7e-05 0 -0 0</pose>
          <mass>0.018385</mass>
          <inertia>
            <ixx>2.29e-06</ixx>
            <ixy>1.43e-06</ixy>
            <ixz>0</ixz>
            <iyy>4.56e-06</iyy>
            <iyz>0</iyz>
            <izz>4.77e-06</izz>
          </inertia>
        </inertial>
        <collision name='kinova_arm_right_finger_prox_link_collision'>
          <pose>0 0 0 0 -0 0</pose>
          <geometry>
            <mesh>
              <scale>1 1 1</scale>
              <uri>/home/georgiossidiropoulos/catkin_ws/src/ros_kortex/kortex_description/grippers/gen3_lite_2f/meshes/right_finger_prox_link.STL</uri>
            </mesh>
          </geometry>
          <surface>
            <contact>
              <ode/>
            </contact>
            <friction>
              <ode/>
              <torsional>
                <ode/>
              </torsional>
            </friction>
            <bounce/>
          </surface>
          <max_contacts>10</max_contacts>
        </collision>
        <visual name='kinova_arm_right_finger_prox_link_visual'>
          <pose>0 0 0 0 -0 0</pose>
          <geometry>
            <mesh>
              <scale>1 1 1</scale>
              <uri>/home/georgiossidiropoulos/catkin_ws/src/ros_kortex/kortex_description/grippers/gen3_lite_2f/meshes/right_finger_prox_link.STL</uri>
            </mesh>
          </geometry>
          <material>
            <script>
              <name>Kortex/Gray</name>
              <uri>file://media/materials/scripts/gazebo.material</uri>
            </script>
          </material>
        </visual>
        <self_collide>0</self_collide>
        <enable_wind>0</enable_wind>
        <kinematic>0</kinematic>
      </link>
      <joint name='kinova_arm_right_finger_tip_joint' type='revolute'>
        <pose relative_to='kinova_arm_right_finger_prox_link'>-0.045636 0.020423 0 0 -0 0</pose>
        <parent>kinova_arm_right_finger_prox_link</parent>
        <child>kinova_arm_right_finger_dist_link</child>
        <axis>
          <xyz>0 0 1</xyz>
          <limit>
            <lower>-0.5</lower>
            <upper>0.21</upper>
            <effort>1000</effort>
            <velocity>1000</velocity>
          </limit>
          <dynamics>
            <spring_reference>0</spring_reference>
            <spring_stiffness>0</spring_stiffness>
          </dynamics>
        </axis>
      </joint>
      <link name='kinova_arm_right_finger_dist_link'>
        <pose relative_to='kinova_arm_right_finger_tip_joint'>0 0 0 0 -0 0</pose>
        <inertial>
          <pose>0.018488 0.001109 0 0 -0 0</pose>
          <mass>0.010748</mass>
          <inertia>
            <ixx>6.3e-07</ixx>
            <ixy>3.2e-07</ixy>
            <ixz>0</ixz>
            <iyy>1.83e-06</iyy>
            <iyz>0</iyz>
            <izz>1.61e-06</izz>
          </inertia>
        </inertial>
        <collision name='kinova_arm_right_finger_dist_link_collision'>
          <pose>0 0 0 0 -0 0</pose>
          <geometry>
            <mesh>
              <scale>1 1 1</scale>
              <uri>/home/georgiossidiropoulos/catkin_ws/src/ros_kortex/kortex_description/grippers/gen3_lite_2f/meshes/right_finger_dist_link.STL</uri>
            </mesh>
          </geometry>
          <surface>
            <contact>
              <ode/>
            </contact>
            <friction>
              <ode/>
              <torsional>
                <ode/>
              </torsional>
            </friction>
            <bounce/>
          </surface>
          <max_contacts>10</max_contacts>
        </collision>
        <visual name='kinova_arm_right_finger_dist_link_visual'>
          <pose>0 0 0 0 -0 0</pose>
          <geometry>
            <mesh>
              <scale>1 1 1</scale>
              <uri>/home/georgiossidiropoulos/catkin_ws/src/ros_kortex/kortex_description/grippers/gen3_lite_2f/meshes/right_finger_dist_link.STL</uri>
            </mesh>
          </geometry>
          <material>
            <script>
              <name>Kortex/Blue</name>
              <uri>file://media/materials/scripts/gazebo.material</uri>
            </script>
          </material>
        </visual>
        <self_collide>0</self_collide>
        <enable_wind>0</enable_wind>
        <kinematic>0</kinematic>
      </link>
      <joint name='rear_left_wheel' type='revolute'>
        <pose relative_to='base_link'>-0.131 0.187795 0.0345 0 -0 0</pose>
        <parent>base_link</parent>
        <child>rear_left_wheel_link</child>
        <axis>
          <xyz>0 1 0</xyz>
          <limit>
            <lower>-1e+16</lower>
            <upper>1e+16</upper>
          </limit>
          <dynamics>
            <spring_reference>0</spring_reference>
            <spring_stiffness>0</spring_stiffness>
          </dynamics>
        </axis>
      </joint>
      <link name='rear_left_wheel_link'>
        <pose relative_to='rear_left_wheel'>0 0 0 0 -0 0</pose>
        <inertial>
          <pose>0 0 0 0 -0 0</pose>
          <mass>0.477</mass>
          <inertia>
            <ixx>0.0013</ixx>
            <ixy>0</ixy>
            <ixz>0</ixz>
            <iyy>0.0024</iyy>
            <iyz>0</iyz>
            <izz>0.0013</izz>
          </inertia>
        </inertial>
        <collision name='rear_left_wheel_link_collision'>
          <pose>0 0 0 1.5708 -0 0</pose>
          <geometry>
            <cylinder>
              <length>0.04</length>
              <radius>0.098</radius>
            </cylinder>
          </geometry>
          <surface>
            <contact>
              <ode>
                <kp>1e+07</kp>
                <kd>1</kd>
              </ode>
            </contact>
            <friction>
              <ode>
                <mu>0.5</mu>
                <mu2>0.5</mu2>
                <fdir1>1 0 0</fdir1>
              </ode>
              <torsional>
                <ode/>
              </torsional>
            </friction>
            <bounce/>
          </surface>
          <max_contacts>10</max_contacts>
        </collision>
        <visual name='rear_left_wheel_link_visual'>
          <pose>0 0 0 1.5708 -0 0</pose>
          <geometry>
            <mesh>
              <scale>1 1 1</scale>
              <uri>/opt/ros/noetic/share/jackal_description/meshes/jackal-wheel.stl</uri>
            </mesh>
          </geometry>
          <material>
            <script>
              <name>Gazebo/DarkGrey</name>
              <uri>file://media/materials/scripts/gazebo.material</uri>
            </script>
          </material>
        </visual>
        <self_collide>0</self_collide>
        <enable_wind>0</enable_wind>
        <kinematic>0</kinematic>
      </link>
      <joint name='rear_right_wheel' type='revolute'>
        <pose relative_to='base_link'>-0.131 -0.187795 0.0345 0 -0 0</pose>
        <parent>base_link</parent>
        <child>rear_right_wheel_link</child>
        <axis>
          <xyz>0 1 0</xyz>
          <limit>
            <lower>-1e+16</lower>
            <upper>1e+16</upper>
          </limit>
          <dynamics>
            <spring_reference>0</spring_reference>
            <spring_stiffness>0</spring_stiffness>
          </dynamics>
        </axis>
      </joint>
      <link name='rear_right_wheel_link'>
        <pose relative_to='rear_right_wheel'>0 0 0 0 -0 0</pose>
        <inertial>
          <pose>0 0 0 0 -0 0</pose>
          <mass>0.477</mass>
          <inertia>
            <ixx>0.0013</ixx>
            <ixy>0</ixy>
            <ixz>0</ixz>
            <iyy>0.0024</iyy>
            <iyz>0</iyz>
            <izz>0.0013</izz>
          </inertia>
        </inertial>
        <collision name='rear_right_wheel_link_collision'>
          <pose>0 0 0 1.5708 -0 0</pose>
          <geometry>
            <cylinder>
              <length>0.04</length>
              <radius>0.098</radius>
            </cylinder>
          </geometry>
          <surface>
            <contact>
              <ode>
                <kp>1e+07</kp>
                <kd>1</kd>
              </ode>
            </contact>
            <friction>
              <ode>
                <mu>0.5</mu>
                <mu2>0.5</mu2>
                <fdir1>1 0 0</fdir1>
              </ode>
              <torsional>
                <ode/>
              </torsional>
            </friction>
            <bounce/>
          </surface>
          <max_contacts>10</max_contacts>
        </collision>
        <visual name='rear_right_wheel_link_visual'>
          <pose>0 0 0 1.5708 -0 0</pose>
          <geometry>
            <mesh>
              <scale>1 1 1</scale>
              <uri>/opt/ros/noetic/share/jackal_description/meshes/jackal-wheel.stl</uri>
            </mesh>
          </geometry>
          <material>
            <script>
              <name>Gazebo/DarkGrey</name>
              <uri>file://media/materials/scripts/gazebo.material</uri>
            </script>
          </material>
        </visual>
        <self_collide>0</self_collide>
        <enable_wind>0</enable_wind>
        <kinematic>0</kinematic>
      </link>
      <plugin name='gazebo_ros_control' filename='libgazebo_ros_control.so'>
        <robotNamespace>/</robotNamespace>
      </plugin>
      <plugin name='imu_controller' filename='libhector_gazebo_ros_imu.so'>
        <robotNamespace>/</robotNamespace>
        <updateRate>50.0</updateRate>
        <topicName>imu/data</topicName>
        <accelDrift>0.005 0.005 0.005</accelDrift>
        <accelGaussianNoise>0.005 0.005 0.005</accelGaussianNoise>
        <rateDrift>0.005 0.005 0.005</rateDrift>
        <rateGaussianNoise>0.005 0.005 0.005</rateGaussianNoise>
        <headingDrift>0.005</headingDrift>
        <headingGaussianNoise>0.005</headingGaussianNoise>
        <bodyName>base_link</bodyName>
        <xyzOffset>0 0 0</xyzOffset>
        <rpyOffset>0 -0 0</rpyOffset>
        <ignition::corrected_offsets>1</ignition::corrected_offsets>
      </plugin>
      <static>0</static>
      <plugin name='gps_controller' filename='libhector_gazebo_ros_gps.so'>
        <updateRate>40</updateRate>
        <robotNamespace>/</robotNamespace>
        <frameId>base_link</frameId>
        <topicName>/navsat/fix</topicName>
        <velocityTopicName>/navsat/vel</velocityTopicName>
        <referenceLatitude>49.9</referenceLatitude>
        <referenceLongitude>8.9</referenceLongitude>
        <referenceHeading>90</referenceHeading>
        <referenceAltitude>0</referenceAltitude>
        <drift>0.0001 0.0001 0.0001</drift>
        <bodyName>base_link</bodyName>
        <xyzOffset>-0.18 0.126 0.1815</xyzOffset>
        <rpyOffset>0 -0 0</rpyOffset>
        <ignition::corrected_offsets>1</ignition::corrected_offsets>
      </plugin>
      <pose>0 0 1 0 -0 0</pose>
    </model>
    <model name='unit_sphere'>
      <pose>-0.816737 -0.162443 0.5 0 -0 0</pose>
      <link name='link'>
        <inertial>
          <mass>1</mass>
          <inertia>
            <ixx>0.1</ixx>
            <ixy>0</ixy>
            <ixz>0</ixz>
            <iyy>0.1</iyy>
            <iyz>0</iyz>
            <izz>0.1</izz>
          </inertia>
          <pose>0 0 0 0 -0 0</pose>
        </inertial>
        <collision name='collision'>
          <geometry>
            <sphere>
              <radius>0.499999</radius>
            </sphere>
          </geometry>
          <max_contacts>10</max_contacts>
          <surface>
            <contact>
              <ode/>
            </contact>
            <bounce/>
            <friction>
              <torsional>
                <ode/>
              </torsional>
              <ode/>
            </friction>
          </surface>
        </collision>
        <visual name='visual'>
          <geometry>
            <sphere>
              <radius>0.499999</radius>
            </sphere>
          </geometry>
          <material>
            <script>
              <name>Gazebo/Grey</name>
              <uri>file://media/materials/scripts/gazebo.material</uri>
            </script>
          </material>
        </visual>
        <gravity>0</gravity>
        <self_collide>0</self_collide>
        <enable_wind>0</enable_wind>
        <kinematic>0</kinematic>
      </link>
    </model>
  </world>
</sdf>
